{
 "cells": [
  {
   "cell_type": "code",
   "execution_count": 1,
   "id": "50c22396",
   "metadata": {},
   "outputs": [
    {
     "name": "stderr",
     "output_type": "stream",
     "text": [
      "Using TensorFlow backend.\n"
     ]
    }
   ],
   "source": [
    "import os\n",
    "from os import listdir\n",
    "from PIL import Image as Image\n",
    "from numpy import asarray\n",
    "from numpy import expand_dims\n",
    "from matplotlib import pyplot\n",
    "from keras.models import load_model\n",
    "import numpy as np\n",
    "import tensorflow as tf\n",
    "\n",
    "import pickle\n",
    "import cv2"
   ]
  },
  {
   "cell_type": "code",
   "execution_count": 2,
   "id": "8f195bc6",
   "metadata": {
    "scrolled": true
   },
   "outputs": [
    {
     "name": "stderr",
     "output_type": "stream",
     "text": [
      "C:\\Users\\diego\\.conda\\envs\\py34\\lib\\site-packages\\keras\\engine\\saving.py:341: UserWarning: No training configuration found in save file: the model was *not* compiled. Compile it manually.\n",
      "  warnings.warn('No training configuration found in save file: '\n"
     ]
    }
   ],
   "source": [
    "HaarCascade = cv2.CascadeClassifier('cascades/data/haarcascade_frontalface_alt2.xml')\n",
    "facenet = load_model('facenet_keras.h5')\n",
    "model = tf.keras.models.load_model(\"test.h5\")\n",
    "\n",
    "# load the model from disk\n",
    "knn = pickle.load(open('knn', 'rb'))\n",
    "svm = pickle.load(open('svm', 'rb'))"
   ]
  },
  {
   "cell_type": "code",
   "execution_count": 3,
   "id": "2189399c",
   "metadata": {},
   "outputs": [
    {
     "name": "stdout",
     "output_type": "stream",
     "text": [
      "Model: \"sequential\"\n",
      "_________________________________________________________________\n",
      "Layer (type)                 Output Shape              Param #   \n",
      "=================================================================\n",
      "dense (Dense)                (None, 64)                8256      \n",
      "_________________________________________________________________\n",
      "dropout (Dropout)            (None, 64)                0         \n",
      "_________________________________________________________________\n",
      "dense_1 (Dense)              (None, 2)                 130       \n",
      "=================================================================\n",
      "Total params: 8,386\n",
      "Trainable params: 8,386\n",
      "Non-trainable params: 0\n",
      "_________________________________________________________________\n"
     ]
    }
   ],
   "source": [
    "model.summary()"
   ]
  },
  {
   "cell_type": "code",
   "execution_count": 4,
   "id": "123a8af9",
   "metadata": {},
   "outputs": [],
   "source": [
    "#load labels\n",
    "labels = {}\n",
    "with open(\"labels.picle\", \"rb\") as f:\n",
    "    og_labels = pickle.load(f)\n",
    "    labels = {v:k for k,v in og_labels.items()}"
   ]
  },
  {
   "cell_type": "code",
   "execution_count": 5,
   "id": "3ec6d881",
   "metadata": {},
   "outputs": [],
   "source": [
    "def get_embedding(facenet, face_pixels):\n",
    "    face_pixels = face_pixels.astype('float32')\n",
    "    \n",
    "    mean,std = face_pixels.mean(), face_pixels.std()\n",
    "    face_pixels = (face_pixels-mean) / std\n",
    "    \n",
    "    samples = np.expand_dims(face_pixels, axis=0)\n",
    "    yhat = facenet.predict(samples)\n",
    "    return yhat[0]"
   ]
  },
  {
   "cell_type": "code",
   "execution_count": 6,
   "id": "12d8b905",
   "metadata": {},
   "outputs": [],
   "source": [
    "def valid_predict(predicao):\n",
    "    if predicao[0][0] >= 0.7:\n",
    "        return True\n",
    "    if predicao[0][1] >= 0.7:\n",
    "        return True\n",
    "    return False"
   ]
  },
  {
   "cell_type": "markdown",
   "id": "bfbd48a8",
   "metadata": {},
   "source": [
    "# SVM"
   ]
  },
  {
   "cell_type": "code",
   "execution_count": null,
   "id": "80bb0301",
   "metadata": {},
   "outputs": [
    {
     "name": "stderr",
     "output_type": "stream",
     "text": [
      "ERROR:root:Internal Python error in the inspect module.\n",
      "Below is the traceback from this internal error.\n",
      "\n",
      "ERROR:root:Internal Python error in the inspect module.\n",
      "Below is the traceback from this internal error.\n",
      "\n",
      "ERROR:root:Internal Python error in the inspect module.\n",
      "Below is the traceback from this internal error.\n",
      "\n"
     ]
    },
    {
     "name": "stdout",
     "output_type": "stream",
     "text": [
      "Traceback (most recent call last):\n",
      "  File \"C:\\Users\\diego\\.conda\\envs\\py34\\lib\\site-packages\\IPython\\core\\interactiveshell.py\", line 3444, in run_code\n",
      "    exec(code_obj, self.user_global_ns, self.user_ns)\n",
      "  File \"C:\\Users\\diego\\AppData\\Local\\Temp/ipykernel_8036/2411783401.py\", line 19, in <module>\n",
      "    confianca = svm.predict_proba(tensor)\n",
      "  File \"C:\\Users\\diego\\.conda\\envs\\py34\\lib\\site-packages\\sklearn\\utils\\metaestimators.py\", line 109, in __get__\n",
      "    if not self.check(obj):\n",
      "  File \"C:\\Users\\diego\\.conda\\envs\\py34\\lib\\site-packages\\sklearn\\svm\\_base.py\", line 801, in _check_proba\n",
      "    \"predict_proba is not available when  probability=False\"\n",
      "AttributeError: predict_proba is not available when  probability=False\n",
      "\n",
      "During handling of the above exception, another exception occurred:\n",
      "\n",
      "Traceback (most recent call last):\n",
      "  File \"C:\\Users\\diego\\.conda\\envs\\py34\\lib\\site-packages\\IPython\\core\\interactiveshell.py\", line 2064, in showtraceback\n",
      "    stb = value._render_traceback_()\n",
      "AttributeError: 'AttributeError' object has no attribute '_render_traceback_'\n",
      "\n",
      "During handling of the above exception, another exception occurred:\n",
      "\n",
      "Traceback (most recent call last):\n",
      "  File \"C:\\Users\\diego\\.conda\\envs\\py34\\lib\\site-packages\\IPython\\core\\ultratb.py\", line 1101, in get_records\n",
      "    return _fixed_getinnerframes(etb, number_of_lines_of_context, tb_offset)\n",
      "  File \"C:\\Users\\diego\\.conda\\envs\\py34\\lib\\site-packages\\IPython\\core\\ultratb.py\", line 248, in wrapped\n",
      "    return f(*args, **kwargs)\n",
      "  File \"C:\\Users\\diego\\.conda\\envs\\py34\\lib\\site-packages\\IPython\\core\\ultratb.py\", line 281, in _fixed_getinnerframes\n",
      "    records = fix_frame_records_filenames(inspect.getinnerframes(etb, context))\n",
      "  File \"C:\\Users\\diego\\.conda\\envs\\py34\\lib\\inspect.py\", line 1502, in getinnerframes\n",
      "    frameinfo = (tb.tb_frame,) + getframeinfo(tb, context)\n",
      "  File \"C:\\Users\\diego\\.conda\\envs\\py34\\lib\\inspect.py\", line 1460, in getframeinfo\n",
      "    filename = getsourcefile(frame) or getfile(frame)\n",
      "  File \"C:\\Users\\diego\\.conda\\envs\\py34\\lib\\inspect.py\", line 696, in getsourcefile\n",
      "    if getattr(getmodule(object, filename), '__loader__', None) is not None:\n",
      "  File \"C:\\Users\\diego\\.conda\\envs\\py34\\lib\\inspect.py\", line 733, in getmodule\n",
      "    if ismodule(module) and hasattr(module, '__file__'):\n",
      "  File \"C:\\Users\\diego\\.conda\\envs\\py34\\lib\\site-packages\\tensorflow\\__init__.py\", line 50, in __getattr__\n",
      "    module = self._load()\n",
      "  File \"C:\\Users\\diego\\.conda\\envs\\py34\\lib\\site-packages\\tensorflow\\__init__.py\", line 44, in _load\n",
      "    module = _importlib.import_module(self.__name__)\n",
      "  File \"C:\\Users\\diego\\.conda\\envs\\py34\\lib\\importlib\\__init__.py\", line 127, in import_module\n",
      "    return _bootstrap._gcd_import(name[level:], package, level)\n",
      "  File \"<frozen importlib._bootstrap>\", line 1006, in _gcd_import\n",
      "  File \"<frozen importlib._bootstrap>\", line 983, in _find_and_load\n",
      "  File \"<frozen importlib._bootstrap>\", line 965, in _find_and_load_unlocked\n",
      "ModuleNotFoundError: No module named 'tensorflow_core.estimator'\n",
      "Traceback (most recent call last):\n",
      "  File \"C:\\Users\\diego\\.conda\\envs\\py34\\lib\\site-packages\\IPython\\core\\interactiveshell.py\", line 3444, in run_code\n",
      "    exec(code_obj, self.user_global_ns, self.user_ns)\n",
      "  File \"C:\\Users\\diego\\AppData\\Local\\Temp/ipykernel_8036/2411783401.py\", line 19, in <module>\n",
      "    confianca = svm.predict_proba(tensor)\n",
      "  File \"C:\\Users\\diego\\.conda\\envs\\py34\\lib\\site-packages\\sklearn\\utils\\metaestimators.py\", line 109, in __get__\n",
      "    if not self.check(obj):\n",
      "  File \"C:\\Users\\diego\\.conda\\envs\\py34\\lib\\site-packages\\sklearn\\svm\\_base.py\", line 801, in _check_proba\n",
      "    \"predict_proba is not available when  probability=False\"\n",
      "AttributeError: predict_proba is not available when  probability=False\n",
      "\n",
      "During handling of the above exception, another exception occurred:\n",
      "\n",
      "Traceback (most recent call last):\n",
      "  File \"C:\\Users\\diego\\.conda\\envs\\py34\\lib\\site-packages\\IPython\\core\\interactiveshell.py\", line 2064, in showtraceback\n",
      "    stb = value._render_traceback_()\n",
      "AttributeError: 'AttributeError' object has no attribute '_render_traceback_'\n",
      "\n",
      "During handling of the above exception, another exception occurred:\n",
      "\n",
      "Traceback (most recent call last):\n",
      "  File \"C:\\Users\\diego\\.conda\\envs\\py34\\lib\\site-packages\\IPython\\core\\interactiveshell.py\", line 3364, in run_ast_nodes\n",
      "    if (await self.run_code(code, result,  async_=asy)):\n",
      "  File \"C:\\Users\\diego\\.conda\\envs\\py34\\lib\\site-packages\\IPython\\core\\interactiveshell.py\", line 3461, in run_code\n",
      "    self.showtraceback(running_compiled_code=True)\n",
      "  File \"C:\\Users\\diego\\.conda\\envs\\py34\\lib\\site-packages\\IPython\\core\\interactiveshell.py\", line 2067, in showtraceback\n",
      "    value, tb, tb_offset=tb_offset)\n",
      "  File \"C:\\Users\\diego\\.conda\\envs\\py34\\lib\\site-packages\\IPython\\core\\ultratb.py\", line 1368, in structured_traceback\n",
      "    self, etype, value, tb, tb_offset, number_of_lines_of_context)\n",
      "  File \"C:\\Users\\diego\\.conda\\envs\\py34\\lib\\site-packages\\IPython\\core\\ultratb.py\", line 1268, in structured_traceback\n",
      "    self, etype, value, tb, tb_offset, number_of_lines_of_context\n",
      "  File \"C:\\Users\\diego\\.conda\\envs\\py34\\lib\\site-packages\\IPython\\core\\ultratb.py\", line 1125, in structured_traceback\n",
      "    tb_offset)\n",
      "  File \"C:\\Users\\diego\\.conda\\envs\\py34\\lib\\site-packages\\IPython\\core\\ultratb.py\", line 1082, in format_exception_as_a_whole\n",
      "    last_unique, recursion_repeat = find_recursion(orig_etype, evalue, records)\n",
      "  File \"C:\\Users\\diego\\.conda\\envs\\py34\\lib\\site-packages\\IPython\\core\\ultratb.py\", line 382, in find_recursion\n",
      "    return len(records), 0\n",
      "TypeError: object of type 'NoneType' has no len()\n",
      "\n",
      "During handling of the above exception, another exception occurred:\n",
      "\n",
      "Traceback (most recent call last):\n",
      "  File \"C:\\Users\\diego\\.conda\\envs\\py34\\lib\\site-packages\\IPython\\core\\interactiveshell.py\", line 2064, in showtraceback\n",
      "    stb = value._render_traceback_()\n",
      "AttributeError: 'TypeError' object has no attribute '_render_traceback_'\n",
      "\n",
      "During handling of the above exception, another exception occurred:\n",
      "\n",
      "Traceback (most recent call last):\n",
      "  File \"C:\\Users\\diego\\.conda\\envs\\py34\\lib\\site-packages\\IPython\\core\\ultratb.py\", line 1101, in get_records\n",
      "    return _fixed_getinnerframes(etb, number_of_lines_of_context, tb_offset)\n",
      "  File \"C:\\Users\\diego\\.conda\\envs\\py34\\lib\\site-packages\\IPython\\core\\ultratb.py\", line 248, in wrapped\n",
      "    return f(*args, **kwargs)\n",
      "  File \"C:\\Users\\diego\\.conda\\envs\\py34\\lib\\site-packages\\IPython\\core\\ultratb.py\", line 281, in _fixed_getinnerframes\n",
      "    records = fix_frame_records_filenames(inspect.getinnerframes(etb, context))\n",
      "  File \"C:\\Users\\diego\\.conda\\envs\\py34\\lib\\inspect.py\", line 1502, in getinnerframes\n",
      "    frameinfo = (tb.tb_frame,) + getframeinfo(tb, context)\n",
      "  File \"C:\\Users\\diego\\.conda\\envs\\py34\\lib\\inspect.py\", line 1460, in getframeinfo\n",
      "    filename = getsourcefile(frame) or getfile(frame)\n",
      "  File \"C:\\Users\\diego\\.conda\\envs\\py34\\lib\\inspect.py\", line 696, in getsourcefile\n",
      "    if getattr(getmodule(object, filename), '__loader__', None) is not None:\n",
      "  File \"C:\\Users\\diego\\.conda\\envs\\py34\\lib\\inspect.py\", line 733, in getmodule\n",
      "    if ismodule(module) and hasattr(module, '__file__'):\n",
      "  File \"C:\\Users\\diego\\.conda\\envs\\py34\\lib\\site-packages\\tensorflow\\__init__.py\", line 50, in __getattr__\n",
      "    module = self._load()\n",
      "  File \"C:\\Users\\diego\\.conda\\envs\\py34\\lib\\site-packages\\tensorflow\\__init__.py\", line 44, in _load\n",
      "    module = _importlib.import_module(self.__name__)\n",
      "  File \"C:\\Users\\diego\\.conda\\envs\\py34\\lib\\importlib\\__init__.py\", line 127, in import_module\n",
      "    return _bootstrap._gcd_import(name[level:], package, level)\n",
      "  File \"<frozen importlib._bootstrap>\", line 1006, in _gcd_import\n",
      "  File \"<frozen importlib._bootstrap>\", line 983, in _find_and_load\n",
      "  File \"<frozen importlib._bootstrap>\", line 965, in _find_and_load_unlocked\n",
      "ModuleNotFoundError: No module named 'tensorflow_core.estimator'\n",
      "Traceback (most recent call last):\n",
      "  File \"C:\\Users\\diego\\.conda\\envs\\py34\\lib\\site-packages\\IPython\\core\\interactiveshell.py\", line 3444, in run_code\n",
      "    exec(code_obj, self.user_global_ns, self.user_ns)\n",
      "  File \"C:\\Users\\diego\\AppData\\Local\\Temp/ipykernel_8036/2411783401.py\", line 19, in <module>\n",
      "    confianca = svm.predict_proba(tensor)\n",
      "  File \"C:\\Users\\diego\\.conda\\envs\\py34\\lib\\site-packages\\sklearn\\utils\\metaestimators.py\", line 109, in __get__\n",
      "    if not self.check(obj):\n",
      "  File \"C:\\Users\\diego\\.conda\\envs\\py34\\lib\\site-packages\\sklearn\\svm\\_base.py\", line 801, in _check_proba\n",
      "    \"predict_proba is not available when  probability=False\"\n",
      "AttributeError: predict_proba is not available when  probability=False\n",
      "\n",
      "During handling of the above exception, another exception occurred:\n",
      "\n",
      "Traceback (most recent call last):\n",
      "  File \"C:\\Users\\diego\\.conda\\envs\\py34\\lib\\site-packages\\IPython\\core\\interactiveshell.py\", line 2064, in showtraceback\n",
      "    stb = value._render_traceback_()\n",
      "AttributeError: 'AttributeError' object has no attribute '_render_traceback_'\n",
      "\n",
      "During handling of the above exception, another exception occurred:\n",
      "\n",
      "Traceback (most recent call last):\n",
      "  File \"C:\\Users\\diego\\.conda\\envs\\py34\\lib\\site-packages\\IPython\\core\\interactiveshell.py\", line 3364, in run_ast_nodes\n",
      "    if (await self.run_code(code, result,  async_=asy)):\n",
      "  File \"C:\\Users\\diego\\.conda\\envs\\py34\\lib\\site-packages\\IPython\\core\\interactiveshell.py\", line 3461, in run_code\n",
      "    self.showtraceback(running_compiled_code=True)\n",
      "  File \"C:\\Users\\diego\\.conda\\envs\\py34\\lib\\site-packages\\IPython\\core\\interactiveshell.py\", line 2067, in showtraceback\n",
      "    value, tb, tb_offset=tb_offset)\n",
      "  File \"C:\\Users\\diego\\.conda\\envs\\py34\\lib\\site-packages\\IPython\\core\\ultratb.py\", line 1368, in structured_traceback\n",
      "    self, etype, value, tb, tb_offset, number_of_lines_of_context)\n",
      "  File \"C:\\Users\\diego\\.conda\\envs\\py34\\lib\\site-packages\\IPython\\core\\ultratb.py\", line 1268, in structured_traceback\n",
      "    self, etype, value, tb, tb_offset, number_of_lines_of_context\n",
      "  File \"C:\\Users\\diego\\.conda\\envs\\py34\\lib\\site-packages\\IPython\\core\\ultratb.py\", line 1125, in structured_traceback\n",
      "    tb_offset)\n",
      "  File \"C:\\Users\\diego\\.conda\\envs\\py34\\lib\\site-packages\\IPython\\core\\ultratb.py\", line 1082, in format_exception_as_a_whole\n",
      "    last_unique, recursion_repeat = find_recursion(orig_etype, evalue, records)\n",
      "  File \"C:\\Users\\diego\\.conda\\envs\\py34\\lib\\site-packages\\IPython\\core\\ultratb.py\", line 382, in find_recursion\n",
      "    return len(records), 0\n",
      "TypeError: object of type 'NoneType' has no len()\n",
      "\n",
      "During handling of the above exception, another exception occurred:\n",
      "\n",
      "Traceback (most recent call last):\n",
      "  File \"C:\\Users\\diego\\.conda\\envs\\py34\\lib\\site-packages\\IPython\\core\\interactiveshell.py\", line 2064, in showtraceback\n",
      "    stb = value._render_traceback_()\n",
      "AttributeError: 'TypeError' object has no attribute '_render_traceback_'\n",
      "\n",
      "During handling of the above exception, another exception occurred:\n",
      "\n",
      "Traceback (most recent call last):\n",
      "  File \"C:\\Users\\diego\\.conda\\envs\\py34\\lib\\site-packages\\IPython\\core\\interactiveshell.py\", line 2947, in _run_cell\n",
      "    return runner(coro)\n",
      "  File \"C:\\Users\\diego\\.conda\\envs\\py34\\lib\\site-packages\\IPython\\core\\async_helpers.py\", line 68, in _pseudo_sync_runner\n",
      "    coro.send(None)\n",
      "  File \"C:\\Users\\diego\\.conda\\envs\\py34\\lib\\site-packages\\IPython\\core\\interactiveshell.py\", line 3173, in run_cell_async\n",
      "    interactivity=interactivity, compiler=compiler, result=result)\n",
      "  File \"C:\\Users\\diego\\.conda\\envs\\py34\\lib\\site-packages\\IPython\\core\\interactiveshell.py\", line 3383, in run_ast_nodes\n",
      "    self.showtraceback()\n",
      "  File \"C:\\Users\\diego\\.conda\\envs\\py34\\lib\\site-packages\\IPython\\core\\interactiveshell.py\", line 2067, in showtraceback\n",
      "    value, tb, tb_offset=tb_offset)\n",
      "  File \"C:\\Users\\diego\\.conda\\envs\\py34\\lib\\site-packages\\IPython\\core\\ultratb.py\", line 1368, in structured_traceback\n",
      "    self, etype, value, tb, tb_offset, number_of_lines_of_context)\n",
      "  File \"C:\\Users\\diego\\.conda\\envs\\py34\\lib\\site-packages\\IPython\\core\\ultratb.py\", line 1268, in structured_traceback\n",
      "    self, etype, value, tb, tb_offset, number_of_lines_of_context\n",
      "  File \"C:\\Users\\diego\\.conda\\envs\\py34\\lib\\site-packages\\IPython\\core\\ultratb.py\", line 1143, in structured_traceback\n",
      "    chained_exceptions_tb_offset)\n",
      "  File \"C:\\Users\\diego\\.conda\\envs\\py34\\lib\\site-packages\\IPython\\core\\ultratb.py\", line 1082, in format_exception_as_a_whole\n",
      "    last_unique, recursion_repeat = find_recursion(orig_etype, evalue, records)\n",
      "  File \"C:\\Users\\diego\\.conda\\envs\\py34\\lib\\site-packages\\IPython\\core\\ultratb.py\", line 382, in find_recursion\n",
      "    return len(records), 0\n",
      "TypeError: object of type 'NoneType' has no len()\n",
      "\n",
      "During handling of the above exception, another exception occurred:\n",
      "\n",
      "Traceback (most recent call last):\n",
      "  File \"C:\\Users\\diego\\.conda\\envs\\py34\\lib\\site-packages\\IPython\\core\\interactiveshell.py\", line 2064, in showtraceback\n",
      "    stb = value._render_traceback_()\n",
      "AttributeError: 'TypeError' object has no attribute '_render_traceback_'\n",
      "\n",
      "During handling of the above exception, another exception occurred:\n",
      "\n",
      "Traceback (most recent call last):\n",
      "  File \"C:\\Users\\diego\\.conda\\envs\\py34\\lib\\site-packages\\IPython\\core\\ultratb.py\", line 1101, in get_records\n",
      "    return _fixed_getinnerframes(etb, number_of_lines_of_context, tb_offset)\n",
      "  File \"C:\\Users\\diego\\.conda\\envs\\py34\\lib\\site-packages\\IPython\\core\\ultratb.py\", line 248, in wrapped\n",
      "    return f(*args, **kwargs)\n",
      "  File \"C:\\Users\\diego\\.conda\\envs\\py34\\lib\\site-packages\\IPython\\core\\ultratb.py\", line 281, in _fixed_getinnerframes\n",
      "    records = fix_frame_records_filenames(inspect.getinnerframes(etb, context))\n",
      "  File \"C:\\Users\\diego\\.conda\\envs\\py34\\lib\\inspect.py\", line 1502, in getinnerframes\n",
      "    frameinfo = (tb.tb_frame,) + getframeinfo(tb, context)\n",
      "  File \"C:\\Users\\diego\\.conda\\envs\\py34\\lib\\inspect.py\", line 1460, in getframeinfo\n",
      "    filename = getsourcefile(frame) or getfile(frame)\n",
      "  File \"C:\\Users\\diego\\.conda\\envs\\py34\\lib\\inspect.py\", line 696, in getsourcefile\n",
      "    if getattr(getmodule(object, filename), '__loader__', None) is not None:\n",
      "  File \"C:\\Users\\diego\\.conda\\envs\\py34\\lib\\inspect.py\", line 733, in getmodule\n",
      "    if ismodule(module) and hasattr(module, '__file__'):\n",
      "  File \"C:\\Users\\diego\\.conda\\envs\\py34\\lib\\site-packages\\tensorflow\\__init__.py\", line 50, in __getattr__\n",
      "    module = self._load()\n",
      "  File \"C:\\Users\\diego\\.conda\\envs\\py34\\lib\\site-packages\\tensorflow\\__init__.py\", line 44, in _load\n",
      "    module = _importlib.import_module(self.__name__)\n",
      "  File \"C:\\Users\\diego\\.conda\\envs\\py34\\lib\\importlib\\__init__.py\", line 127, in import_module\n",
      "    return _bootstrap._gcd_import(name[level:], package, level)\n",
      "  File \"<frozen importlib._bootstrap>\", line 1006, in _gcd_import\n",
      "  File \"<frozen importlib._bootstrap>\", line 983, in _find_and_load\n",
      "  File \"<frozen importlib._bootstrap>\", line 965, in _find_and_load_unlocked\n",
      "ModuleNotFoundError: No module named 'tensorflow_core.estimator'\n"
     ]
    }
   ],
   "source": [
    "cap = cv2.VideoCapture(0)\n",
    "#cap = cv2.VideoCapture('./Dataset/Teste/Dessa/Dessa.mp4')\n",
    "frame_number = 0\n",
    "while(True):\n",
    "    #get frame by frame\n",
    "    ret, frame = cap.read()\n",
    "    \n",
    "    faces = HaarCascade.detectMultiScale(frame, scaleFactor=1.5, minNeighbors=5)\n",
    "    for (x, y, w, h) in faces:\n",
    "        roi = frame[y:y+w, x:x+h,:]\n",
    "        roi = Image.fromarray(roi)                       \n",
    "        roi = roi.resize((160,160))\n",
    "        roi = asarray(roi)\n",
    "        roi_norm = roi.astype(\"float32\")/255\n",
    "        emb = get_embedding(facenet, roi_norm)\n",
    "        tensor = np.expand_dims(emb, axis=0)\n",
    "        #predicao = model.predict(tensor)\n",
    "        predicao = svm.predict(tensor)\n",
    "        #confianca = max(round(predicao[0][0],3),round(predicao[0][1],3))*100\n",
    "        classe = np.argmax(predicao)\n",
    "        #BOX\n",
    "        color = (255,0,0) #BGR\n",
    "        stroke = 2\n",
    "        width = x + w\n",
    "        height = y + h\n",
    "        cv2.rectangle(frame,(x,y), (width, height), color, stroke)\n",
    "        cv2.putText(frame, labels.get(classe), (x, y+10), \n",
    "                    cv2.FONT_HERSHEY_SIMPLEX, 0.9, color, 2)\n",
    "        cv2.imwrite('./Dataset/Recognition/' + labels.get(classe)+str(frame_number) + '.jpg',roi)\n",
    "        frame_number += 1\n",
    "            \n",
    "\n",
    "    cv2.imshow('.frame',frame)\n",
    "    if cv2.waitKey(20) & 0xFF == ord('q'):\n",
    "        break"
   ]
  },
  {
   "cell_type": "markdown",
   "id": "ba307d6b",
   "metadata": {},
   "source": [
    "# MLP"
   ]
  },
  {
   "cell_type": "code",
   "execution_count": null,
   "id": "ca4948bc",
   "metadata": {},
   "outputs": [],
   "source": [
    "cap = cv2.VideoCapture(0)\n",
    "#cap = cv2.VideoCapture('./Dataset/Teste/Dessa/Dessa.mp4')\n",
    "frame_number = 0\n",
    "while(True):\n",
    "    #get frame by frame\n",
    "    ret, frame = cap.read()\n",
    "    \n",
    "    faces = HaarCascade.detectMultiScale(frame, scaleFactor=1.5, minNeighbors=5)\n",
    "    for (x, y, w, h) in faces:\n",
    "        roi = frame[y:y+w, x:x+h,:]\n",
    "        roi = Image.fromarray(roi)                       \n",
    "        roi = roi.resize((160,160))\n",
    "        roi = asarray(roi)\n",
    "        roi_norm = roi.astype(\"float32\")/255\n",
    "        emb = get_embedding(facenet, roi_norm)\n",
    "        tensor = np.expand_dims(emb, axis=0)\n",
    "        predicao = model.predict(tensor)\n",
    "        if valid_predict(predicao):\n",
    "            confianca = max(round(predicao[0][0],3),round(predicao[0][1],3))*100\n",
    "            classe = np.argmax(predicao)\n",
    "            #BOX\n",
    "            color = (255,0,0) #BGR\n",
    "            stroke = 2\n",
    "            width = x + w\n",
    "            height = y + h\n",
    "            cv2.rectangle(frame,(x,y), (width, height), color, stroke)\n",
    "            cv2.putText(frame, labels.get(classe) + \" \" + str(int(confianca)) + '%', (x, y+10), \n",
    "                        cv2.FONT_HERSHEY_SIMPLEX, 0.9, color, 2)\n",
    "            cv2.imwrite('./Dataset/Recognition/' + labels.get(classe)+str(frame_number) + '.jpg',roi)\n",
    "            frame_number += 1\n",
    "            \n",
    "\n",
    "    cv2.imshow('.frame',frame)\n",
    "    if cv2.waitKey(20) & 0xFF == ord('q'):\n",
    "        break"
   ]
  },
  {
   "cell_type": "code",
   "execution_count": null,
   "id": "dfc30f94",
   "metadata": {},
   "outputs": [],
   "source": []
  },
  {
   "cell_type": "code",
   "execution_count": null,
   "id": "a4ab949f",
   "metadata": {},
   "outputs": [],
   "source": []
  },
  {
   "cell_type": "code",
   "execution_count": null,
   "id": "c63ef3c3",
   "metadata": {},
   "outputs": [],
   "source": []
  },
  {
   "cell_type": "code",
   "execution_count": null,
   "id": "1a1caf55",
   "metadata": {},
   "outputs": [],
   "source": []
  }
 ],
 "metadata": {
  "kernelspec": {
   "display_name": "Python 3 (ipykernel)",
   "language": "python",
   "name": "python3"
  },
  "language_info": {
   "codemirror_mode": {
    "name": "ipython",
    "version": 3
   },
   "file_extension": ".py",
   "mimetype": "text/x-python",
   "name": "python",
   "nbconvert_exporter": "python",
   "pygments_lexer": "ipython3",
   "version": "3.7.4"
  }
 },
 "nbformat": 4,
 "nbformat_minor": 5
}
